Workbook

Sheet retail_sales_2023
A1: Order_ID | B1: Order_Date | C1: Customer_ID | D1: Customer_Name | E1: Region | F1: Category | G1: Product_Name | H1: Quantity | I1: Unit_Price | J1: Discount | K1: Sales | L1: Profit | M1: Revenue | N1: Quarter | O1: Profit Percentage | P1: City | Q1: Segment
A2: ORD006312 | B2: 45065 | C2: CUST0260 | D2: Timothy Nori | E2: South | F2: Books | G2: Excel for Beginners | H2: 3 | I2: 671.24 | J2: 0 | K2: 2013.72 | L2: 689.84 | M2: =H2*I2*(1-J2) -> 2013.72 | N2: ="Q"&ROUNDUP(MONTH(B2)/3,0) -> Q2 | O2: =(L2/K2)*100 -> 34.256997 | P2: =VLOOKUP(retail_sales_2023!C2,customers!A:J,5,) -> Kochi | Q2: =VLOOKUP(C2,customers!A:J,10,0) -> Regular
A3: ORD008688 | B3: 45066 | C3: CUST0223 | D3: Aarini Dugar | E3: East | F3: Furniture | G3: Wooden Study Table | H3: 3 | I3: 21336.22 | J3: 0 | K3: 64008.66 | L3: 16168.33 | M3: =H3*I3*(1-J3) -> 64008.66 | N3: ="Q"&ROUNDUP(MONTH(B3)/3,0) -> Q2 | O3: =(L3/K3)*100 -> 25.259598 | P3: =VLOOKUP(retail_sales_2023!C3,customers!A:J,5,) -> Guwahati | Q3: =VLOOKUP(C3,customers!A:J,10,0) -> Premium
A4: ORD007579 | B4: 45137 | C4: CUST0258 | D4: Sanaya Khalsa | E4: North | F4: Sports | G4: Running Shoes | H4: 1 | I4: 649.49 | J4: 0.3 | K4: 454.64 | L4: 126.47 | M4: =H4*I4*(1-J4) -> 454.643 | N4: ="Q"&ROUNDUP(MONTH(B4)/3,0) -> Q3 | O4: =(L4/K4)*100 -> 27.817614 | P4: =VLOOKUP(retail_sales_2023!C4,customers!A:J,5,) -> Delhi | Q4: =VLOOKUP(C4,customers!A:J,10,0) -> Premium
A5: ORD004768 | B5: 45017 | C5: CUST0037 | D5: Janani Sawhney | E5: West | F5: Furniture | G5: Shoe Rack | H5: 4 | I5: 41779.66 | J5: 0.2 | K5: 133694.91 | L5: 39801.41 | M5: =H5*I5*(1-J5) -> 133694.91 | N5: ="Q"&ROUNDUP(MONTH(B5)/3,0) -> Q2 | O5: =(L5/K5)*100 -> 29.770326 | P5: =VLOOKUP(retail_sales_2023!C5,customers!A:J,5,) -> Ahmedabad | Q5: =VLOOKUP(C5,customers!A:J,10,0) -> Premium
A6: ORD006089 | B6: 45137 | C6: CUST0044 | D6: Advay Nadig | E6: North | F6: Toys | G6: Board Game Monopoly | H6: 5 | I6: 3035.91 | J6: 0.05 | K6: 14420.57 | L6: 2873.99 | M6: =H6*I6*(1-J6) -> 14420.572 | N6: ="Q"&ROUNDUP(MONTH(B6)/3,0) -> Q3 | O6: =(L6/K6)*100 -> 19.929795 | P6: =VLOOKUP(retail_sales_2023!C6,customers!A:J,5,) -> Lucknow | Q6: =VLOOKUP(C6,customers!A:J,10,0) -> Premium
A7: ORD004604 | B7: 45073 | C7: CUST0221 | D7: Naveen Dass | E7: South | F7: Electronics | G7: 4K Smart TV | H7: 4 | I7: 25815.94 | J7: 0.05 | K7: 98100.57 | L7: 11250.48 | M7: =H7*I7*(1-J7) -> 98100.572 | N7: ="Q"&ROUNDUP(MONTH(B7)/3,0) -> Q2 | O7: =(L7/K7)*100 -> 11.468313 | P7: =VLOOKUP(retail_sales_2023!C7,customers!A:J,5,) -> Kochi | Q7: =VLOOKUP(C7,customers!A:J,10,0) -> Regular
A8: ORD007001 | B8: 45016 | C8: CUST0435 | D8: Ekalinga Chowdhury | E8: East | F8: Toys | G8: LEGO City Set | H8: 5 | I8: 2120.52 | J8: 0 | K8: 10602.6 | L8: 3680.74 | M8: =H8*I8*(1-J8) -> 10602.6 | N8: ="Q"&ROUNDUP(MONTH(B8)/3,0) -> Q1 | O8: =(L8/K8)*100 -> 34.715447 | P8: =VLOOKUP(retail_sales_2023!C8,customers!A:J,5,) -> Bhubaneswar | Q8: =VLOOKUP(C8,customers!A:J,10,0) -> Premium
A9: ORD005992 | B9: 44942 | C9: CUST0266 | D9: Tanay Sane | E9: East | F9: Groceries | G9: Sunflower Oil 1L | H9: 4 | I9: 496.51 | J9: 0 | K9: 1986.04 | L9: 198.32 | M9: =H9*I9*(1-J9) -> 1986.04 | N9: ="Q"&ROUNDUP(MONTH(B9)/3,0) -> Q1 | O9: =(L9/K9)*100 -> 9.9857002 | P9: =VLOOKUP(retail_sales_2023!C9,customers!A:J,5,) -> Patna | Q9: =VLOOKUP(C9,customers!A:J,10,0) -> Premium
A10: ORD000840 | B10: 45104 | C10: CUST0113 | D10: Harita Chaudhari | E10: North | F10: Sports | G10: Gym Gloves | H10: 2 | I10: 4112.32 | J10: 0.15 | K10: 6990.94 | L10: 1727.97 | M10: =H10*I10*(1-J10) -> 6990.944 | N10: ="Q"&ROUNDUP(MONTH(B10)/3,0) -> Q2 | O10: =(L10/K10)*100 -> 24.717277 | P10: =VLOOKUP(retail_sales_2023!C10,customers!A:J,5,) -> Lucknow | Q10: =VLOOKUP(C10,customers!A:J,10,0) -> Premium
A11: ORD003889 | B11: 45061 | C11: CUST0306 | D11: Aahana Agarwal | E11: West | F11: Sports | G11: Jump Rope | H11: 1 | I11: 5036.18 | J11: 0 | K11: 5036.18 | L11: 829.34 | M11: =H11*I11*(1-J11) -> 5036.18 | N11: ="Q"&ROUNDUP(MONTH(B11)/3,0) -> Q2 | O11: =(L11/K11)*100 -> 16.46764 | P11: =VLOOKUP(retail_sales_2023!C11,customers!A:J,5,) -> Nagpur | Q11: =VLOOKUP(C11,customers!A:J,10,0) -> Premium
A12: ORD007133 | B12: 45044 | C12: CUST0020 | D12: Neelima Menon | E12: East | F12: Toys | G12: Action Figure Pack | H12: 2 | I12: 3890.76 | J12: 0 | K12: 7781.52 | L12: 1530.84 | M12: =H12*I12*(1-J12) -> 7781.52 | N12: ="Q"&ROUNDUP(MONTH(B12)/3,0) -> Q2 | O12: =(L12/K12)*100 -> 19.672763 | P12: =VLOOKUP(retail_sales_2023!C12,customers!A:J,5,) -> Guwahati | Q12: =VLOOKUP(C12,customers!A:J,10,0) -> Regular
A13: ORD000527 | B13: 44987 | C13: CUST0134 | D13: Hemang Bhavsar | E13: West | F13: Groceries | G13: Oats 1kg | H13: 1 | I13: 464.5 | J13: 0.3 | K13: 325.15 | L13: 23.12 | M13: =H13*I13*(1-J13) -> 325.15 | N13: ="Q"&ROUNDUP(MONTH(B13)/3,0) -> Q1 | O13: =(L13/K13)*100 -> 7.1105644 | P13: =VLOOKUP(retail_sales_2023!C13,customers!A:J,5,) -> Surat | Q13: =VLOOKUP(C13,customers!A:J,10,0) -> Premium
... A79: ORD009486 | B79: 45168 | C79: CUST0030 | D79: Kashvi Sahota | E79: North | F79: Toys | G79: Building Blocks | H79: 2 | I79: 3097.62 | J79: 0 | K79: 6195.24 | L79: 2070.72 | M79: =H79*I79*(1-J79) -> 6195.24 | N79: ="Q"&ROUNDUP(MONTH(B79)/3,0) -> Q3 | O79: =(L79/K79)*100 -> 33.424371 | P79: =VLOOKUP(retail_sales_2023!C79,customers!A:J,5,) -> Delhi | Q79: =VLOOKUP(C79,customers!A:J,10,0) -> Premium
A80: ORD002385 | B80: 44986 | C80: CUST0285 | D80: Mitesh Padmanabhan | E80: West | F80: Clothing | G80: Casual Shorts | H80: 0 | I80: 2549.72 | J80: 0 | K80: 0 | L80: 0 | M80: =H80*I80*(1-J80) -> 0 | N80: ="Q"&ROUNDUP(MONTH(B80)/3,0) -> Q1 | O80: 0 | P80: =VLOOKUP(retail_sales_2023!C80,customers!A:J,5,) -> Pune | Q80: =VLOOKUP(C80,customers!A:J,10,0) -> Premium
A81: ORD010947 | B81: 45282 | C81: CUST0477 | D81: Teerth Bobal | E81: East | F81: Books | G81: Machine Learning A-Z | H81: 1 | I81: 757.58 | J81: 0 | K81: 757.58 | L81: 236.9 | M81: =H81*I81*(1-J81) -> 757.58 | N81: ="Q"&ROUNDUP(MONTH(B81)/3,0) -> Q4 | O81: =(L81/K81)*100 -> 31.270625 | P81: =VLOOKUP(retail_sales_2023!C81,customers!A:J,5,) -> Patna | Q81: =VLOOKUP(C81,customers!A:J,10,0) -> Occasional
A82: ORD002706 | B82: 45037 | C82: CUST0023 | D82: Udyati Dâ€™Alia | E82: West | F82: Electronics | G82: Tablet Pro | H82: 5 | I82: 12177.73 | J82: 0.1 | K82: 54799.78 | L82: 5120.14 | M82: =H82*I82*(1-J82) -> 54799.785 | N82: ="Q"&ROUNDUP(MONTH(B82)/3,0) -> Q2 | O82: =(L82/K82)*100 -> 9.3433587 | P82: =VLOOKUP(retail_sales_2023!C82,customers!A:J,5,) -> Mumbai | Q82: =VLOOKUP(C82,customers!A:J,10,0) -> Regular
A83: ORD006451 | B83: 44933 | C83: CUST0477 | D83: Teerth Bobal | E83: East | F83: Electronics | G83: Smartphone X12 | H83: 5 | I83: 33411.97 | J83: 0.1 | K83: 150353.87 | L83: 21925.55 | M83: =H83*I83*(1-J83) -> 150353.87 | N83: ="Q"&ROUNDUP(MONTH(B83)/3,0) -> Q1 | O83: =(L83/K83)*100 -> 14.582631 | P83: =VLOOKUP(retail_sales_2023!C83,customers!A:J,5,) -> Patna | Q83: =VLOOKUP(C83,customers!A:J,10,0) -> Occasional
A84: ORD008860 | B84: 45235 | C84: CUST0429 | D84: Daniel Rau | E84: North | F84: Books | G84: Leadership 101 | H84: 4 | I84: 845.82 | J84: 0.05 | K84: 3214.12 | L84: 1389.1 | M84: =H84*I84*(1-J84) -> 3214.116 | N84: ="Q"&ROUNDUP(MONTH(B84)/3,0) -> Q4 | O84: =(L84/K84)*100 -> 43.218673 | P84: =VLOOKUP(retail_sales_2023!C84,customers!A:J,5,) -> Jaipur | Q84: =VLOOKUP(C84,customers!A:J,10,0) -> Premium
A85: ORD011405 | B85: 44988 | C85: CUST0127 | D85: Upma Sanghvi | E85: East | F85: Electronics | G85: Laptop 15" | H85: 5 | I85: 37707.69 | J85: 0.25 | K85: 141403.84 | L85: 15241.73 | M85: =H85*I85*(1-J85) -> 141403.84 | N85: ="Q"&ROUNDUP(MONTH(B85)/3,0) -> Q1 | O85: =(L85/K85)*100 -> 10.778866 | P85: =VLOOKUP(retail_sales_2023!C85,customers!A:J,5,) -> Patna | Q85: =VLOOKUP(C85,customers!A:J,10,0) -> Occasional
A86: ORD001746 | B86: 44974 | C86: CUST0047 | D86: Chameli Dani | E86: East | F86: Electronics | G86: Wireless Headphones | H86: 1 | I86: 35714.08 | J86: 0 | K86: 35714.08 | L86: 4936.18 | M86: =H86*I86*(1-J86) -> 35714.08 | N86: ="Q"&ROUNDUP(MONTH(B86)/3,0) -> Q1 | O86: =(L86/K86)*100 -> 13.821384 | P86: =VLOOKUP(retail_sales_2023!C86,customers!A:J,5,) -> Patna | Q86: =VLOOKUP(C86,customers!A:J,10,0) -> Regular
A87: ORD010292 | B87: 45018 | C87: CUST0263 | D87: Jacob Radhakrishnan | E87: East | F87: Furniture | G87: 3-Seater Sofa | H87: 2 | I87: 7624.45 | J87: 0 | K87: 15248.9 | L87: 3176.57 | M87: =H87*I87*(1-J87) -> 15248.9 | N87: ="Q"&ROUNDUP(MONTH(B87)/3,0) -> Q2 | O87: =(L87/K87)*100 -> 20.83147 | P87: =VLOOKUP(retail_sales_2023!C87,customers!A:J,5,) -> Kolkata | Q87: =VLOOKUP(C87,customers!A:J,10,0) -> Premium
A88: ORD006710 | B88: 45176 | C88: CUST0454 | D88: Avi Kar | E88: East | F88: Books | G88: Python Programming | H88: 2 | I88: 398.96 | J88: 0 | K88: 797.92 | L88: 250.02 | M88: =H88*I88*(1-J88) -> 797.92 | N88: ="Q"&ROUNDUP(MONTH(B88)/3,0) -> Q3 | O88: =(L88/K88)*100 -> 31.333968 | P88: =VLOOKUP(retail_sales_2023!C88,customers!A:J,5,) -> Patna | Q88: =VLOOKUP(C88,customers!A:J,10,0) -> Regular
A89: ORD011951 | B89: 44956 | C89: CUST0215 | D89: Kamya Apte | E89: West | F89: Electronics | G89: Smartwatch | H89: 4 | I89: 3635.76 | J89: 0 | K89: 14543.04 | L89: 2229.38 | M89: =H89*I89*(1-J89) -> 14543.04 | N89: ="Q"&ROUNDUP(MONTH(B89)/3,0) -> Q1 | O89: =(L89/K89)*100 -> 15.329532 | P89: =VLOOKUP(retail_sales_2023!C89,customers!A:J,5,) -> Surat | Q89: =VLOOKUP(C89,customers!A:J,10,0) -> Premium
A90: ORD002699 | B90: 45203 | C90: CUST0410 | D90: Matthew Sule | E90: North | F90: Books | G90: Digital Marketing | H90: 5 | I90: 553.03 | J90: 0.05 | K90: 2626.89 | L90: 1182.36 | M90: =H90*I90*(1-J90) -> 2626.8925 | N90: ="Q"&ROUNDUP(MONTH(B90)/3,0) -> Q4 | O90: =(L90/K90)*100 -> 45.009879 | P90: =VLOOKUP(retail_sales_2023!C90,customers!A:J,5,) -> Amritsar | Q90: =VLOOKUP(C90,customers!A:J,10,0) -> Premium
A91: ORD001424 | B91: 45116 | C91: CUST0469 | D91: Brinda Doshi | E91: South | F91: Sports | G91: Resistance Bands | H91: 3 | I91: 3137.33 | J91: 0.1 | K91: 8470.79 | L91: 2061.56 | M91: =H91*I91*(1-J91) -> 8470.791 | N91: ="Q"&ROUNDUP(MONTH(B91)/3,0) -> Q3 | O91: =(L91/K91)*100 -> 24.337281 | P91: =VLOOKUP(retail_sales_2023!C91,customers!A:J,5,) -> Kochi | Q91: =VLOOKUP(C91,customers!A:J,10,0) -> Regular
A92: ORD001062 | B92: 45149 | C92: CUST0052 | D92: Vivaan Parmer | E92: East | F92: Sports | G92: Resistance Bands | H92: 4 | I92: 2168.37 | J92: 0 | K92: 8673.48 | L92: 1454.75 | M92: =H92*I92*(1-J92) -> 8673.48 | N92: ="Q"&ROUNDUP(MONTH(B92)/3,0) -> Q3 | O92: =(L92/K92)*100 -> 16.772391 | P92: =VLOOKUP(retail_sales_2023!C92,customers!A:J,5,) -> Bhubaneswar | Q92: =VLOOKUP(C92,customers!A:J,10,0) -> Occasional
... A225: ORD009696 | B225: 45247 | C225: CUST0161 | D225: Jalsa Narang | E225: North | F225: Groceries | G225: Mixed Nuts 500g | H225: 6 | I225: 545.81 | J225: 0 | K225: 3274.86 | L225: 259.86 | M225: =H225*I225*(1-J225) -> 3274.86 | N225: ="Q"&ROUNDUP(MONTH(B225)/3,0) -> Q4 | O225: =(L225/K225)*100 -> 7.9349957 | P225: =VLOOKUP(retail_sales_2023!C225,customers!A:J,5,) -> Lucknow | Q225: =VLOOKUP(C225,customers!A:J,10,0) -> Premium
A226: ORD008293 | B226: 45077 | C226: CUST0223 | D226: Aarini Dugar | E226: East | F226: Electronics | G226: Tablet Pro | H226: 0 | I226: 40088 | J226: 0.15 | K226: 0 | L226: 0 | M226: =H226*I226*(1-J226) -> 0 | N226: ="Q"&ROUNDUP(MONTH(B226)/3,0) -> Q2 | O226: 0 | P226: =VLOOKUP(retail_sales_2023!C226,customers!A:J,5,) -> Guwahati | Q226: =VLOOKUP(C226,customers!A:J,10,0) -> Premium
A227: ORD007075 | B227: 45069 | C227: CUST0317 | D227: Balendra Soman | E227: West | F227: Clothing | G227: Men Formal Shirt | H227: 1 | I227: 1055.81 | J227: 0.25 | K227: 791.86 | L227: 177.36 | M227: =H227*I227*(1-J227) -> 791.8575 | N227: ="Q"&ROUNDUP(MONTH(B227)/3,0) -> Q2 | O227: =(L227/K227)*100 -> 22.397899 | P227: =VLOOKUP(retail_sales_2023!C227,customers!A:J,5,) -> Nagpur | Q227: =VLOOKUP(C227,customers!A:J,10,0) -> Occasional
A228: ORD002009 | B228: 45251 | C228: CUST0300 | D228: Maanav Kashyap | E228: North | F228: Sports | G228: Cycling Helmet | H228: 4 | I228: 5959.73 | J228: 0.2 | K228: 19071.14 | L228: 4403.71 | M228: =H228*I228*(1-J228) -> 19071.136 | N228: ="Q"&ROUNDUP(MONTH(B228)/3,0) -> Q4 | O228: =(L228/K228)*100 -> 23.090964 | P228: =VLOOKUP(retail_sales_2023!C228,customers!A:J,5,) -> Amritsar | Q228: =VLOOKUP(C228,customers!A:J,10,0) -> Premium
A229: ORD006553 | B229: 45165 | C229: CUST0095 | D229: Pahal Goyal | E229: North | F229: Sports | G229: Cricket Bat | H229: 4 | I229: 2576.2 | J229: 0.1 | K229: 9274.32 | L229: 2328.5 | M229: =H229*I229*(1-J229) -> 9274.32 | N229: ="Q"&ROUNDUP(MONTH(B229)/3,0) -> Q3 | O229: =(L229/K229)*100 -> 25.106962 | P229: =VLOOKUP(retail_sales_2023!C229,customers!A:J,5,) -> Jaipur | Q229: =VLOOKUP(C229,customers!A:J,10,0) -> Premium
A230: ORD010185 | B230: 45001 | C230: CUST0454 | D230: Avi Kar | E230: East | F230: Groceries | G230: Organic Honey 500g | H230: 1 | I230: 733.4 | J230: 0.2 | K230: 586.72 | L230: 45.87 | M230: =H230*I230*(1-J230) -> 586.72 | N230: ="Q"&ROUNDUP(MONTH(B230)/3,0) -> Q1 | O230: =(L230/K230)*100 -> 7.8180393 | P230: =VLOOKUP(retail_sales_2023!C230,customers!A:J,5,) -> Patna | Q230: =VLOOKUP(C230,customers!A:J,10,0) -> Regular
A231: ORD002645 | B231: 45115 | C231: CUST0495 | D231: Chanchal Golla | E231: North | F231: Sports | G231: Running Shoes | H231: 5 | I231: 3306.85 | J231: 0 | K231: 16534.25 | L231: 4455.44 | M231: =H231*I231*(1-J231) -> 16534.25 | N231: ="Q"&ROUNDUP(MONTH(B231)/3,0) -> Q3 | O231: =(L231/K231)*100 -> 26.946732 | P231: =VLOOKUP(retail_sales_2023!C231,customers!A:J,5,) -> Amritsar | Q231: =VLOOKUP(C231,customers!A:J,10,0) -> Premium
A232: ORD007274 | B232: 45181 | C232: CUST0019 | D232: Saksham Pillay | E232: West | F232: Furniture | G232: Shoe Rack | H232: 3 | I232: 19095.49 | J232: 0.1 | K232: 51557.82 | L232: 13308.76 | M232: =H232*I232*(1-J232) -> 51557.823 | N232: ="Q"&ROUNDUP(MONTH(B232)/3,0) -> Q3 | O232: =(L232/K232)*100 -> 25.813271 | P232: =VLOOKUP(retail_sales_2023!C232,customers!A:J,5,) -> Surat | Q232: =VLOOKUP(C232,customers!A:J,10,0) -> Regular
A233: ORD004885 | B233: 44931 | C233: CUST0287 | D233: Harish Sahota | E233: North | F233: Toys | G233: Barbie Doll Set | H233: 4 | I233: 2382.14 | J233: 0.15 | K233: 8099.28 | L233: 2620.28 | M233: =H233*I233*(1-J233) -> 8099.276 | N233: ="Q"&ROUNDUP(MONTH(B233)/3,0) -> Q1 | O233: =(L233/K233)*100 -> 32.352012 | P233: =VLOOKUP(retail_sales_2023!C233,customers!A:J,5,) -> Delhi | Q233: =VLOOKUP(C233,customers!A:J,10,0) -> Regular
A234: ORD011157 | B234: 45110 | C234: CUST0433 | D234: Oliver Ram | E234: South | F234: Groceries | G234: Sunflower Oil 1L | H234: 3 | I234: 456.13 | J234: 0.1 | K234: 1231.55 | L234: 73.52 | M234: =H234*I234*(1-J234) -> 1231.551 | N234: ="Q"&ROUNDUP(MONTH(B234)/3,0) -> Q3 | O234: =(L234/K234)*100 -> 5.969713 | P234: =VLOOKUP(retail_sales_2023!C234,customers!A:J,5,) -> Kochi | Q234: =VLOOKUP(C234,customers!A:J,10,0) -> Premium
A235: ORD008010 | B235: 45063 | C235: CUST0269 | D235: Fiyaz Verma | E235: West | F235: Groceries | G235: Instant Coffee 200g | H235: 2 | I235: 112.94 | J235: 0.05 | K235: 214.59 | L235: 19.02 | M235: =H235*I235*(1-J235) -> 214.586 | N235: ="Q"&ROUNDUP(MONTH(B235)/3,0) -> Q2 | O235: =(L235/K235)*100 -> 8.863414 | P235: =VLOOKUP(retail_sales_2023!C235,customers!A:J,5,) -> Mumbai | Q235: =VLOOKUP(C235,customers!A:J,10,0) -> Premium
A236: ORD010975 | B236: 45115 | C236: CUST0250 | D236: Vanya Subramaniam | E236: West | F236: Furniture | G236: 3-Seater Sofa | H236: 1 | I236: 2843.84 | J236: 0.15 | K236: 2417.26 | L236: 689.21 | M236: =H236*I236*(1-J236) -> 2417.264 | N236: ="Q"&ROUNDUP(MONTH(B236)/3,0) -> Q3 | O236: =(L236/K236)*100 -> 28.512034 | P236: =VLOOKUP(retail_sales_2023!C236,customers!A:J,5,) -> Surat | Q236: =VLOOKUP(C236,customers!A:J,10,0) -> Premium
A237: ORD002138 | B237: 45251 | C237: CUST0242 | D237: Vanya Bhat | E237: North | F237: Groceries | G237: Organic Honey 500g | H237: 9 | I237: 344.46 | J237: 0.25 | K237: 2325.11 | L237: 161.86 | M237: =H237*I237*(1-J237) -> 2325.105 | N237: ="Q"&ROUNDUP(MONTH(B237)/3,0) -> Q4 | O237: =(L237/K237)*100 -> 6.9613911 | P237: =VLOOKUP(retail_sales_2023!C237,customers!A:J,5,) -> Delhi | Q237: =VLOOKUP(C237,customers!A:J,10,0) -> Regular
...

Sheet customers
A1: Customer_ID | B1: Customer_Name | C1: Age | D1: Gender | E1: City | F1: Region | G1: Email | H1: Phone | I1: Join_Date | J1: Segment
A2: CUST0001 | B2: Aditya Bhakta | C2: 40 | D2: Female | E2: Delhi | F2: North | G2: alexander80@example.com | H2: 1828609487 | I2: 44466 | J2: Regular
A3: CUST0002 | B3: Nitara Dhawan | C3: 39 | D3: Male | E3: Chandigarh | F3: North | G3: suleekansh@example.com | H3: 3400231805 | I3: 44635 | J3: Premium
A4: CUST0003 | B4: Avi Johal | C4: 33 | D4: Female | E4: Patna | F4: East | G4: ghosemohammed@example.net | H4: 5471899671 | I4: 44578 | J4: Regular
A5: CUST0004 | B5: Lucky Aggarwal | C5: 62 | D5: Female | E5: Coimbatore | F5: South | G5: guhaamaira@example.com | H5: 1476165635 | I5: 44475 | J5: Premium
A6: CUST0005 | B6: Mason Dutt | C6: 34 | D6: Male | E6: Coimbatore | F6: South | G6: miteshdara@example.com | H6: 915171000000 | I6: 44282 | J6: Regular
A7: CUST0006 | B7: Yashica Nagi | C7: 44 | D7: Female | E7: Hyderabad | F7: South | G7: anitadube@example.org | H7: 917525000000 | I7: 44667 | J7: Regular
A8: CUST0007 | B8: Advika Gopal | C8: 57 | D8: Female | E8: Lucknow | F8: North | G8: aishani21@example.net | H8: 918951000000 | I8: 44713 | J8: Premium
A9: CUST0008 | B9: Sanya Memon | C9: 41 | D9: Female | E9: Lucknow | F9: North | G9: ganga35@example.net | H9: 7030304786 | I9: 44486 | J9: Occasional
A10: CUST0009 | B10: Gayathri Sankar | C10: 37 | D10: Male | E10: Surat | F10: West | G10: ridhi99@example.net | H10: 915324000000 | I10: 44484 | J10: Occasional
A11: CUST0010 | B11: Jack Goyal | C11: 60 | D11: Female | E11: Delhi | F11: North | G11: jkala@example.com | H11: 1172095314 | I11: 44208 | J11: Premium
A12: CUST0011 | B12: Xiti Dash | C12: 37 | D12: Other | E12: Jaipur | F12: North | G12: charvi89@example.org | H12: 3958350979 | I12: 44771 | J12: Regular
A13: CUST0012 | B13: Bina Sha | C13: 44 | D13: Male | E13: Chandigarh | F13: North | G13: jack02@example.net | H13: 9162411682 | I13: 44618 | J13: Occasional
... A501: CUST0500 | B501: Pooja Mand | C501: 52 | D501: Male | E501: Kochi | F501: South | G501: zansimane@example.net | H501: 6693060167 | I501: 44714 | J501: Premium

Sheet Monthly Target
A1: Region | B1: Category | C1: Month | D1: Month_Num | E1: Year | F1: Sales_Target | G1: Sales_Actual | H1: Achievement_Pct
A2: North | B2: Electronics | C2: Jan | D2: 1 | E2: 2023 | F2: 479513.19 | G2: 416944.16 | H2: 87
A3: North | B3: Electronics | C3: Feb | D3: 2 | E3: 2023 | F3: 571830.99 | G3: 495489.64 | H3: 86.6
A4: North | B4: Electronics | C4: Mar | D4: 3 | E4: 2023 | F4: 566601.65 | G4: 481131.18 | H4: 84.9
A5: North | B5: Electronics | C5: Apr | D5: 4 | E5: 2023 | F5: 500765.34 | G5: 544017.49 | H5: 108.6
A6: North | B6: Electronics | C6: May | D6: 5 | E6: 2023 | F6: 548309.22 | G6: 636262.75 | H6: 116
A7: North | B7: Electronics | C7: Jun | D7: 6 | E7: 2023 | F7: 552271.25 | G7: 574961.48 | H7: 104.1
A8: North | B8: Electronics | C8: Jul | D8: 7 | E8: 2023 | F8: 613946.43 | G8: 636131.49 | H8: 103.6
A9: North | B9: Electronics | C9: Aug | D9: 8 | E9: 2023 | F9: 559476.96 | G9: 473032.71 | H9: 84.5
A10: North | B10: Electronics | C10: Sep | D10: 9 | E10: 2023 | F10: 499031.94 | G10: 506329.71 | H10: 101.5
A11: North | B11: Electronics | C11: Oct | D11: 10 | E11: 2023 | F11: 673555.91 | G11: 518961.92 | H11: 77
A12: North | B12: Electronics | C12: Nov | D12: 11 | E12: 2023 | F12: 705294.54 | G12: 611755.9 | H12: 86.7
A13: North | B13: Electronics | C13: Dec | D13: 12 | E13: 2023 | F13: 753451.11 | G13: 638115.84 | H13: 84.7
... A337: West | B337: Toys | C337: Dec | D337: 12 | E337: 2023 | F337: 561972.21 | G337: 632010.13 | H337: 112.5

Sheet Monthly Trend
A3: Monthly Trend | B3: Column Labels
A4: Row Labels | B4: Jan | C4: Feb | D4: Mar | E4: Apr | F4: May | G4: Jun | H4: Jul | I4: Aug | J4: Sep | K4: Oct | L4: Nov | M4: Dec | N4: Grand Total
A5: Smartwatch | B5: 0.085830955 | C5: 0.16445474 | D5: 0.11514491 | E5: 0.09822174 | F5: 0.075444499 | G5: 0.10787905 | H5: 0.17217343 | I5: 0.10501928 | J5: 0.070196394 | K5: 0.12190264 | L5: 0.09786467 | M5: 0.1502429 | N5: 0.11381951
A6: USB-C Hub | B6: 0.10259464 | C6: 0.07785882 | D6: 0.15411958 | E6: 0.13289349 | F6: 0.11565431 | G6: 0.12535124 | H6: 0.071712662 | I6: 0.10379689 | J6: 0.13939756 | K6: 0.098020271 | L6: 0.08669454 | M6: 0.12254635 | N6: 0.11149972
A7: Gaming Mouse | B7: 0.11959411 | C7: 0.13385068 | D7: 0.07368924 | E7: 0.064844937 | F7: 0.079074669 | G7: 0.12939953 | H7: 0.11390706 | I7: 0.10057886 | J7: 0.16913706 | K7: 0.10688041 | L7: 0.11578721 | M7: 0.053080991 | N7: 0.10338214
A8: Smartphone X12 | B8: 0.11785513 | C8: 0.10741281 | D8: 0.072238953 | E8: 0.13207818 | F8: 0.082148033 | G8: 0.075779776 | H8: 0.078335798 | I8: 0.0704842 | J8: 0.12860299 | K8: 0.14525467 | L8: 0.093537546 | M8: 0.11672287 | N8: 0.10198056
A9: DSLR Camera | B9: 0.065345218 | C9: 0.092489172 | D9: 0.10348269 | E9: 0.081557847 | F9: 0.088026574 | G9: 0.11607466 | H9: 0.10398845 | I9: 0.082770259 | J9: 0.12325509 | K9: 0.14642313 | L9: 0.11505809 | M9: 0.10743992 | N9: 0.10154973
A10: Bluetooth Speaker | B10: 0.10591034 | C10: 0.11069696 | D10: 0.068687317 | E10: 0.1021722 | F10: 0.1251365 | G10: 0.11509628 | H10: 0.10321597 | I10: 0.10544368 | J10: 0.068197743 | K10: 0.09798696 | L10: 0.10245127 | M10: 0.091348015 | N10: 0.099579682
A11: Wireless Headphones | B11: 0.12796079 | C11: 0.050783041 | D11: 0.1066577 | E11: 0.083413966 | F11: 0.16032314 | G11: 0.14699304 | H11: 0.1012576 | I11: 0.079147758 | J11: 0.03560371 | K11: 0.092097686 | L11: 0.089858939 | M11: 0.076364213 | N11: 0.096072887
A12: Tablet Pro | B12: 0.11063535 | C12: 0.08495562 | D12: 0.088154259 | E12: 0.094829978 | F12: 0.10355232 | G12: 0.059107808 | H12: 0.1358617 | I12: 0.085882016 | J12: 0.087199932 | K12: 0.044597652 | L12: 0.10024039 | M12: 0.10754897 | N12: 0.09252139
A13: 4K Smart TV | B13: 0.10203427 | C13: 0.056221582 | D13: 0.14711033 | E13: 0.1097974 | F13: 0.093472054 | G13: 0.045714548 | H13: 0.059082143 | I13: 0.14589692 | J13: 0.077495075 | K13: 0.072791374 | L13: 0.1260854 | M13: 0.063791014 | N13: 0.091970676
A14: Laptop 15" | B14: 0.062239203 | C14: 0.12127659 | D14: 0.070715021 | E14: 0.10019026 | F14: 0.077167898 | G14: 0.078604079 | H14: 0.060465187 | I14: 0.12098012 | J14: 0.10091445 | K14: 0.074045211 | L14: 0.072421942 | M14: 0.11091476 | N14: 0.08762371
A15: Grand Total | B15: 1 | C15: 1 | D15: 1 | E15: 1 | F15: 1 | G15: 1 | H15: 1 | I15: 1 | J15: 1 | K15: 1 | L15: 1 | M15: 1 | N15: 1

Sheet sales by region & category
A3: Sum of Sales | B3: Column Labels
A4: Row Labels | B4: East | C4: North | D4: South | E4: West | F4: Grand Total
A5: Electronics | B5: 65737536 | C5: 72703282 | D5: 80109467 | E5: 77666210 | F5: 2.9621649e+08
A6: Furniture | B6: 17138443 | C6: 19742386 | D6: 19015020 | E6: 20393202 | F6: 76289050
A7: Sports | B7: 3248987.5 | C7: 4086190.1 | D7: 4599040.9 | E7: 4158238.5 | F7: 16092457
A8: Clothing | B8: 3995106.8 | C8: 3704436.6 | D8: 3935745.3 | E8: 4116469 | F8: 15751758
A9: Toys | B9: 1809723.9 | C9: 1562760.4 | D9: 1864400.3 | E9: 1664874.7 | F9: 6901759.3
A10: Groceries | B10: 1258422.4 | C10: 1464371.5 | D10: 1459382.8 | E10: 1419683.5 | F10: 5601860.2
A11: Books | B11: 342808.98 | C11: 364810 | D11: 410061.68 | E11: 431290.12 | F11: 1548970.8
A12: Grand Total | B12: 93531029 | C12: 1.0362824e+08 | D12: 1.1139312e+08 | E12: 1.0984997e+08 | F12: 4.1840235e+08

Sheet Target VS Actual
A1: Region | B1: (All)
A3: Month | B3: Sum of Sales_Target | C3: Sum of Sales_Actual | D3: Profit Flag
A4: Jan | B4: 13354606 | C4: 13872884 | D4: =GETPIVOTDATA("Sum of Sales_Actual",$A$3,"Month","Jan")-GETPIVOTDATA("Sum of Sales_Target",$A$3,"Month","Jan") -> 518277.7
A5: Feb | B5: 13266311 | C5: 13193652 | D5: =GETPIVOTDATA("Sum of Sales_Actual",$A$3,"Month","Feb")-GETPIVOTDATA("Sum of Sales_Target",$A$3,"Month","Feb") -> -72658.37
A6: Mar | B6: 13684420 | C6: 13302713 | D6: =GETPIVOTDATA("Sum of Sales_Actual",$A$3,"Month","Mar")-GETPIVOTDATA("Sum of Sales_Target",$A$3,"Month","Mar") -> -381707.54
A7: Apr | B7: 13555186 | C7: 13709245 | D7: =GETPIVOTDATA("Sum of Sales_Actual",$A$3,"Month","Apr")-GETPIVOTDATA("Sum of Sales_Target",$A$3,"Month","Apr") -> 154058.53
A8: May | B8: 13351079 | C8: 14064046 | D8: =GETPIVOTDATA("Sum of Sales_Actual",$A$3,"Month","May")-GETPIVOTDATA("Sum of Sales_Target",$A$3,"Month","May") -> 712967.02
A9: Jun | B9: 14816711 | C9: 14613462 | D9: =GETPIVOTDATA("Sum of Sales_Actual",$A$3,"Month","Jun")-GETPIVOTDATA("Sum of Sales_Target",$A$3,"Month","Jun") -> -203248.89 | G9: Regions | H9: Sum of Achievement_Pct
A10: Jul | B10: 15098457 | C10: 15733101 | D10: =GETPIVOTDATA("Sum of Sales_Actual",$A$3,"Month","Jul")-GETPIVOTDATA("Sum of Sales_Target",$A$3,"Month","Jul") -> 634644.43 | G10: East | H10: 0.25350779
A11: Aug | B11: 13414462 | C11: 13550280 | D11: =GETPIVOTDATA("Sum of Sales_Actual",$A$3,"Month","Aug")-GETPIVOTDATA("Sum of Sales_Target",$A$3,"Month","Aug") -> 135818.39 | G11: North | H11: 0.24832537
A12: Sep | B12: 13371441 | C12: 13297958 | D12: =GETPIVOTDATA("Sum of Sales_Actual",$A$3,"Month","Sep")-GETPIVOTDATA("Sum of Sales_Target",$A$3,"Month","Sep") -> -73482.49 | G12: South | H12: 0.24502184
A13: Oct | B13: 17582003 | C13: 17729357 | D13: =GETPIVOTDATA("Sum of Sales_Actual",$A$3,"Month","Oct")-GETPIVOTDATA("Sum of Sales_Target",$A$3,"Month","Oct") -> 147354.52 | G13: West | H13: 0.25314499
A14: Nov | B14: 17382209 | C14: 17152505 | D14: =GETPIVOTDATA("Sum of Sales_Actual",$A$3,"Month","Nov")-GETPIVOTDATA("Sum of Sales_Target",$A$3,"Month","Nov") -> -229704.39 | G14: Grand Total | H14: 1
A15: Dec | B15: 17683326 | C15: 18577008 | D15: =GETPIVOTDATA("Sum of Sales_Actual",$A$3,"Month","Dec")-GETPIVOTDATA("Sum of Sales_Target",$A$3,"Month","Dec") -> 893681.93
A16: Grand Total | B16: 1.7656021e+08 | C16: 1.7879621e+08 | D16: =SUM(D4:D15) -> 2236000.8
